Traceback (most recent call last):
  File "/Users/dhruvachayapathy/personal/research/mit-research/plasma-data-augmentation/src/utils.py", line 32, in check_wandb_connection
    socket.setdefaulttimeout(timeout)
NameError: name 'socket' is not defined
During handling of the above exception, another exception occurred:
Traceback (most recent call last):
  File "/Users/dhruvachayapathy/personal/research/mit-research/plasma-data-augmentation/src/main.py", line 65, in <module>
    utils.set_up_wandb(
  File "/Users/dhruvachayapathy/personal/research/mit-research/plasma-data-augmentation/src/utils.py", line 17, in set_up_wandb
    if not check_wandb_connection():
  File "/Users/dhruvachayapathy/personal/research/mit-research/plasma-data-augmentation/src/utils.py", line 36, in check_wandb_connection
    except socket.error:
NameError: name 'socket' is not defined