Traceback (most recent call last):
  File "/usr/local/Caskroom/miniconda/base/envs/plasma-aug/lib/python3.10/site-packages/PIL/ImageFile.py", line 536, in _save
    fh = fp.fileno()
AttributeError: '_idat' object has no attribute 'fileno'
During handling of the above exception, another exception occurred:
Traceback (most recent call last):
  File "/Users/dhruvachayapathy/personal/research/mit-research/plasma-data-augmentation/src/main.py", line 74, in <module>
    plot_view(viewmaker, test_dataset[0]['inputs_embeds'].unsqueeze(0).to(device))
  File "/Users/dhruvachayapathy/personal/research/mit-research/plasma-data-augmentation/src/eval.py", line 23, in plot_view
    wandb.log({"Example View":wandb.Image(fig)})
  File "/usr/local/Caskroom/miniconda/base/envs/plasma-aug/lib/python3.10/site-packages/wandb/sdk/data_types/image.py", line 179, in __init__
    self._initialize_from_data(data_or_path, mode, file_type)
  File "/usr/local/Caskroom/miniconda/base/envs/plasma-aug/lib/python3.10/site-packages/wandb/sdk/data_types/image.py", line 302, in _initialize_from_data
    util.ensure_matplotlib_figure(data).savefig(buf, format="png")
  File "/usr/local/Caskroom/miniconda/base/envs/plasma-aug/lib/python3.10/site-packages/matplotlib/figure.py", line 3390, in savefig
    self.canvas.print_figure(fname, **kwargs)
  File "/usr/local/Caskroom/miniconda/base/envs/plasma-aug/lib/python3.10/site-packages/matplotlib/backend_bases.py", line 2193, in print_figure
    result = print_method(
  File "/usr/local/Caskroom/miniconda/base/envs/plasma-aug/lib/python3.10/site-packages/matplotlib/backend_bases.py", line 2043, in <lambda>
    print_method = functools.wraps(meth)(lambda *args, **kwargs: meth(
  File "/usr/local/Caskroom/miniconda/base/envs/plasma-aug/lib/python3.10/site-packages/matplotlib/backends/backend_agg.py", line 497, in print_png
    self._print_pil(filename_or_obj, "png", pil_kwargs, metadata)
  File "/usr/local/Caskroom/miniconda/base/envs/plasma-aug/lib/python3.10/site-packages/matplotlib/backends/backend_agg.py", line 446, in _print_pil
    mpl.image.imsave(
  File "/usr/local/Caskroom/miniconda/base/envs/plasma-aug/lib/python3.10/site-packages/matplotlib/image.py", line 1656, in imsave
    image.save(fname, **pil_kwargs)
  File "/usr/local/Caskroom/miniconda/base/envs/plasma-aug/lib/python3.10/site-packages/PIL/Image.py", line 2439, in save
    save_handler(self, fp, filename)
  File "/usr/local/Caskroom/miniconda/base/envs/plasma-aug/lib/python3.10/site-packages/PIL/PngImagePlugin.py", line 1402, in _save
    ImageFile._save(im, _idat(fp, chunk), [("zip", (0, 0) + im.size, 0, rawmode)])
  File "/usr/local/Caskroom/miniconda/base/envs/plasma-aug/lib/python3.10/site-packages/PIL/ImageFile.py", line 540, in _save
    _encode_tile(im, fp, tile, bufsize, None, exc)
  File "/usr/local/Caskroom/miniconda/base/envs/plasma-aug/lib/python3.10/site-packages/PIL/ImageFile.py", line 559, in _encode_tile
    errcode, data = encoder.encode(bufsize)[1:]
KeyboardInterrupt